Workbook

Sheet METADATA
A1: This is the data workbook for Mimulus Field Survey in the summers of 2021-2022
A2: By: Bolívar Aponte Rolón
A3: Last update: | B3: =TODAY() -> 46040
A6: This book contains information of the field sites (elevation and abbreviation), leaf traits, DNA extraction progress and PCR1 progress.
A7: A capital "Z" has been added to some of the site/population abbreviations as place holders for ease of bioinformatics analyses. This is called Sequen_ID
A8: The most important information is found in the Ch2_FieldSurvey and DNA_PCR_progress sheets. These provide the information for other sheets and child .cvs files (mim2_leaf_traits_field_survey.cvs AND mim2_dna_pcr.csv)

Sheet Ch2_FieldSurvey
A1: Site | B1: Population | C1: Species | D1: Hybrid | E1: Elevation_m | F1: Longitude | G1: Latitude | H1: Sample | I1: Unique_ID | J1: Sample_Date | K1: Sampling_time | L1: Process_Date | M1: Process_time | O1: Unique_ID | P1: Sample_Date | Q1: Sampling_time | R1: Process_Date | S1: Process_time | T1: Leaf_thickness | U1: ACI | V1: Leaf_toughness | W1: LMA(mg) | X1: Light Intensity | Y1: Habitat | Z1: Notes | AA1: ImageJ_1 | AB1: ImageJ_2 | AC1: Leaf_lobe_index | AD1: Notes2
A2: TRTB | B2: TRTB | C2: M. laciniatus | E2: =INDEX(FieldSites!F:F, MATCH(Ch2_FieldSurvey!B2,FieldSites!C:C,0)) -> 1572 | F2: =INDEX(FieldSites!G:G, MATCH(Ch2_FieldSurvey!B2,FieldSites!C:C,0)) -> -119.71015 | G2: =INDEX(FieldSites!H:H, MATCH(Ch2_FieldSurvey!B2,FieldSites!C:C,0)) -> 37.700419 | H2: 1 | I2: TRTB_L1 | J2: 44319 | K2: 0.44722222 | L2: 44319 | M2: 0.86736111 | O2: TRTB_L001 | P2: 5/3/2021 | Q2: 10:44:00 AM | R2: 5/3/2021 | S2: 8:49:00 PM | T2: 410 | U2: 12.2 | V2: 0.29 | W2: 0.7 | AA2: 4905717 | AB2: 4908648 | AC2: =(AB2-AA2)/AB2 -> 0.00059710943
A3: TRTB | B3: TRTB | C3: M. laciniatus | E3: =INDEX(FieldSites!F:F, MATCH(Ch2_FieldSurvey!B3,FieldSites!C:C,0)) -> 1572 | F3: =INDEX(FieldSites!G:G, MATCH(Ch2_FieldSurvey!B3,FieldSites!C:C,0)) -> -119.71015 | G3: =INDEX(FieldSites!H:H, MATCH(Ch2_FieldSurvey!B3,FieldSites!C:C,0)) -> 37.700419 | H3: 1 | I3: TRTB_L1 | J3: 44319 | K3: 0.44722222 | L3: 44319 | M3: 0.90902778 | O3: TRTB_L001 | P3: 5/3/2021 | Q3: 10:44:00 AM | R3: 5/3/2021 | S3: 9:49:00 PM | T3: 620 | U3: 12.2 | V3: 0.46 | W3: 0.4
A4: TRTB | B4: TRTB | C4: M. laciniatus | E4: =INDEX(FieldSites!F:F, MATCH(Ch2_FieldSurvey!B4,FieldSites!C:C,0)) -> 1572 | F4: =INDEX(FieldSites!G:G, MATCH(Ch2_FieldSurvey!B4,FieldSites!C:C,0)) -> -119.71015 | G4: =INDEX(FieldSites!H:H, MATCH(Ch2_FieldSurvey!B4,FieldSites!C:C,0)) -> 37.700419 | H4: 1 | I4: TRTB_L1 | J4: 44319 | K4: 0.44722222 | L4: 44319 | M4: 0.95069444 | O4: TRTB_L001 | P4: 5/3/2021 | Q4: 10:44:00 AM | R4: 5/3/2021 | S4: 10:49:00 PM | T4: 705 | U4: 12.2 | V4: 0.33 | W4: 0.6
A5: FVWB | B5: FVWB | C5: M. guttatus | E5: =INDEX(FieldSites!F:F, MATCH(Ch2_FieldSurvey!B5,FieldSites!C:C,0)) -> 1757 | F5: =INDEX(FieldSites!G:G, MATCH(Ch2_FieldSurvey!B5,FieldSites!C:C,0)) -> -119.70272 | G5: =INDEX(FieldSites!H:H, MATCH(Ch2_FieldSurvey!B5,FieldSites!C:C,0)) -> 37.698587 | H5: 1 | I5: FVWB_G1 | J5: 44319 | K5: 0.58611111 | L5: 44319 | M5: 0.99236111 | O5: FVWB_G001 | P5: 5/3/2021 | Q5: 2:04:00 PM | R5: 5/3/2021 | S5: 11:49:00 PM | T5: 320 | U5: 6.1 | V5: 0.32 | W5: 0.5 | AA5: 293186 | AB5: 308689 | AC5: =(AB5-AA5)/AB5 -> 0.050222068
A6: FVWB | B6: FVWB | C6: M. guttatus | E6: =INDEX(FieldSites!F:F, MATCH(Ch2_FieldSurvey!B6,FieldSites!C:C,0)) -> 1757 | F6: =INDEX(FieldSites!G:G, MATCH(Ch2_FieldSurvey!B6,FieldSites!C:C,0)) -> -119.70272 | G6: =INDEX(FieldSites!H:H, MATCH(Ch2_FieldSurvey!B6,FieldSites!C:C,0)) -> 37.698587 | H6: 1 | I6: FVWB_G1 | J6: 44319 | K6: 0.58611111 | L6: 44319 | M6: 1.0340278 | O6: FVWB_G001 | P6: 5/3/2021 | Q6: 2:04:00 PM | R6: 5/3/2021 | S6: 12:49:00 AM | T6: 315 | U6: 6.1 | V6: 0.33 | W6: 0.5
A7: FVWB | B7: FVWB | C7: M. guttatus | E7: =INDEX(FieldSites!F:F, MATCH(Ch2_FieldSurvey!B7,FieldSites!C:C,0)) -> 1757 | F7: =INDEX(FieldSites!G:G, MATCH(Ch2_FieldSurvey!B7,FieldSites!C:C,0)) -> -119.70272 | G7: =INDEX(FieldSites!H:H, MATCH(Ch2_FieldSurvey!B7,FieldSites!C:C,0)) -> 37.698587 | H7: 1 | I7: FVWB_G1 | J7: 44319 | K7: 0.58611111 | L7: 44319 | M7: 1.0756944 | O7: FVWB_G001 | P7: 5/3/2021 | Q7: 2:04:00 PM | R7: 5/3/2021 | S7: 1:49:00 AM | T7: 342 | U7: 6.1 | V7: 0.3 | W7: 0.8
A8: FVWB | B8: FVWB | C8: M. guttatus | E8: =INDEX(FieldSites!F:F, MATCH(Ch2_FieldSurvey!B8,FieldSites!C:C,0)) -> 1757 | F8: =INDEX(FieldSites!G:G, MATCH(Ch2_FieldSurvey!B8,FieldSites!C:C,0)) -> -119.70272 | G8: =INDEX(FieldSites!H:H, MATCH(Ch2_FieldSurvey!B8,FieldSites!C:C,0)) -> 37.698587 | I8: FVWB_G2 | O8: FVWB_G002 | AA8: 131604 | AB8: 145131 | AC8: =(AB8-AA8)/AB8 -> 0.093205449
A9: BML | B9: BML | C9: M. guttatus | E9: =INDEX(FieldSites!F:F, MATCH(Ch2_FieldSurvey!B9,FieldSites!C:C,0)) -> 1730 | F9: =INDEX(FieldSites!G:G, MATCH(Ch2_FieldSurvey!B9,FieldSites!C:C,0)) -> -119.31401 | G9: =INDEX(FieldSites!H:H, MATCH(Ch2_FieldSurvey!B9,FieldSites!C:C,0)) -> 37.090625 | H9: 1 | I9: BML_G1 | J9: 44321 | K9: 0.48125 | L9: 44322 | M9: 0.90069444 | O9: BMLZ_G001 | P9: 5/5/2021 | Q9: 11:33:00 AM | R9: 5/6/2021 | S9: 9:37:00 PM | T9: 410 | U9: 5 | V9: 0.63 | W9: 0.3 | Z9: ACI measure at proccessing time. | AA9: 483020 | AB9: 586252 | AC9: =(AB9-AA9)/AB9 -> 0.1760881
A10: BML | B10: BML | C10: M. guttatus | E10: =INDEX(FieldSites!F:F, MATCH(Ch2_FieldSurvey!B10,FieldSites!C:C,0)) -> 1730 | F10: =INDEX(FieldSites!G:G, MATCH(Ch2_FieldSurvey!B10,FieldSites!C:C,0)) -> -119.31401 | G10: =INDEX(FieldSites!H:H, MATCH(Ch2_FieldSurvey!B10,FieldSites!C:C,0)) -> 37.090625 | H10: 1 | I10: BML_G1 | J10: 44321 | K10: 0.48125 | L10: 44322 | M10: 0.90069444 | O10: BMLZ_G001 | P10: 5/5/2021 | Q10: 11:33:00 AM | R10: 5/6/2021 | S10: 9:37:00 PM | T10: 300 | U10: 4 | V10: 0.4 | W10: 0.3 | Z10: ACI measure at proccessing time.
A11: BML | B11: BML | C11: M. guttatus | E11: =INDEX(FieldSites!F:F, MATCH(Ch2_FieldSurvey!B11,FieldSites!C:C,0)) -> 1730 | F11: =INDEX(FieldSites!G:G, MATCH(Ch2_FieldSurvey!B11,FieldSites!C:C,0)) -> -119.31401 | G11: =INDEX(FieldSites!H:H, MATCH(Ch2_FieldSurvey!B11,FieldSites!C:C,0)) -> 37.090625 | H11: 1 | I11: BML_G1 | J11: 44321 | K11: 0.48125 | L11: 44322 | M11: 0.90069444 | O11: BMLZ_G001 | P11: 5/5/2021 | Q11: 11:33:00 AM | R11: 5/6/2021 | S11: 9:37:00 PM | T11: 355 | U11: 4.8 | V11: 0.62 | W11: 0.4 | Z11: ACI measure at proccessing time.
A12: BML | B12: BML | C12: M. guttatus | E12: =INDEX(FieldSites!F:F, MATCH(Ch2_FieldSurvey!B12,FieldSites!C:C,0)) -> 1730 | F12: =INDEX(FieldSites!G:G, MATCH(Ch2_FieldSurvey!B12,FieldSites!C:C,0)) -> -119.31401 | G12: =INDEX(FieldSites!H:H, MATCH(Ch2_FieldSurvey!B12,FieldSites!C:C,0)) -> 37.090625 | H12: 2 | I12: BML_G2 | J12: 44321 | K12: 0.48263889 | L12: 44322 | M12: 0.90277778 | O12: BMLZ_G002 | P12: 5/5/2021 | Q12: 11:35:00 AM | R12: 5/6/2021 | S12: 9:40:00 PM | T12: 420 | U12: 3.9 | V12: 0.58 | W12: 0.7 | Z12: ACI measure at proccessing time. | AA12: 933840 | AB12: 1020695 | AC12: =(AB12-AA12)/AB12 -> 0.08509398
A13: BML | B13: BML | C13: M. guttatus | E13: =INDEX(FieldSites!F:F, MATCH(Ch2_FieldSurvey!B13,FieldSites!C:C,0)) -> 1730 | F13: =INDEX(FieldSites!G:G, MATCH(Ch2_FieldSurvey!B13,FieldSites!C:C,0)) -> -119.31401 | G13: =INDEX(FieldSites!H:H, MATCH(Ch2_FieldSurvey!B13,FieldSites!C:C,0)) -> 37.090625 | H13: 2 | I13: BML_G2 | J13: 44321 | K13: 0.48263889 | L13: 44322 | M13: 0.90277778 | O13: BMLZ_G002 | P13: 5/5/2021 | Q13: 11:35:00 AM | R13: 5/6/2021 | S13: 9:40:00 PM | T13: 330 | U13: 4.4 | V13: 0.27 | W13: 1.1 | Z13: ACI measure at proccessing time.
A14: BML | B14: BML | C14: M. guttatus | E14: =INDEX(FieldSites!F:F, MATCH(Ch2_FieldSurvey!B14,FieldSites!C:C,0)) -> 1730 | F14: =INDEX(FieldSites!G:G, MATCH(Ch2_FieldSurvey!B14,FieldSites!C:C,0)) -> -119.31401 | G14: =INDEX(FieldSites!H:H, MATCH(Ch2_FieldSurvey!B14,FieldSites!C:C,0)) -> 37.090625 | H14: 2 | I14: BML_G2 | J14: 44321 | K14: 0.48263889 | L14: 44322 | M14: 0.90277778 | O14: BMLZ_G002 | P14: 5/5/2021 | Q14: 11:35:00 AM | R14: 5/6/2021 | S14: 9:40:00 PM | T14: 290 | U14: 6.6 | V14: 0.59 | W14: 0.5 | Z14: ACI measure at proccessing time.
A15: BML | B15: BML | C15: M. guttatus | E15: =INDEX(FieldSites!F:F, MATCH(Ch2_FieldSurvey!B15,FieldSites!C:C,0)) -> 1730 | F15: =INDEX(FieldSites!G:G, MATCH(Ch2_FieldSurvey!B15,FieldSites!C:C,0)) -> -119.31401 | G15: =INDEX(FieldSites!H:H, MATCH(Ch2_FieldSurvey!B15,FieldSites!C:C,0)) -> 37.090625 | H15: 3 | I15: BML_G3 | J15: 44321 | K15: 0.48263889 | L15: 44322 | M15: 0.90555556 | O15: BMLZ_G003 | P15: 5/5/2021 | Q15: 11:35:00 AM | R15: 5/6/2021 | S15: 9:44:00 PM | T15: 340 | U15: 5.1 | V15: 0.72 | W15: 0.7 | Z15: ACI measure at proccessing time. | AA15: 356347 | AB15: 381527 | AC15: =(AB15-AA15)/AB15 -> 0.06599795
A16: BML | B16: BML | C16: M. guttatus | E16: =INDEX(FieldSites!F:F, MATCH(Ch2_FieldSurvey!B16,FieldSites!C:C,0)) -> 1730 | F16: =INDEX(FieldSites!G:G, MATCH(Ch2_FieldSurvey!B16,FieldSites!C:C,0)) -> -119.31401 | G16: =INDEX(FieldSites!H:H, MATCH(Ch2_FieldSurvey!B16,FieldSites!C:C,0)) -> 37.090625 | H16: 3 | I16: BML_G3 | J16: 44321 | K16: 0.48263889 | L16: 44322 | M16: 0.90555556 | O16: BMLZ_G003 | P16: 5/5/2021 | Q16: 11:35:00 AM | R16: 5/6/2021 | S16: 9:44:00 PM | T16: 380 | U16: 5.3 | V16: 0.46 | W16: 0.7 | Z16: ACI measure at proccessing time.
A17: BML | B17: BML | C17: M. guttatus | E17: =INDEX(FieldSites!F:F, MATCH(Ch2_FieldSurvey!B17,FieldSites!C:C,0)) -> 1730 | F17: =INDEX(FieldSites!G:G, MATCH(Ch2_FieldSurvey!B17,FieldSites!C:C,0)) -> -119.31401 | G17: =INDEX(FieldSites!H:H, MATCH(Ch2_FieldSurvey!B17,FieldSites!C:C,0)) -> 37.090625 | H17: 3 | I17: BML_G3 | J17: 44321 | K17: 0.48263889 | L17: 44322 | M17: 0.90555556 | O17: BMLZ_G003 | P17: 5/5/2021 | Q17: 11:35:00 AM | R17: 5/6/2021 | S17: 9:44:00 PM | T17: 270 | U17: 5.3 | V17: 0.58 | W17: 0.5 | Z17: ACI measure at proccessing time.
A18: BML | B18: BML | C18: M. guttatus | E18: =INDEX(FieldSites!F:F, MATCH(Ch2_FieldSurvey!B18,FieldSites!C:C,0)) -> 1730 | F18: =INDEX(FieldSites!G:G, MATCH(Ch2_FieldSurvey!B18,FieldSites!C:C,0)) -> -119.31401 | G18: =INDEX(FieldSites!H:H, MATCH(Ch2_FieldSurvey!B18,FieldSites!C:C,0)) -> 37.090625 | H18: 4 | I18: BML_G4 | J18: 44321 | K18: 0.48611111 | L18: 44322 | M18: 0.90763889 | O18: BMLZ_G004 | P18: 5/5/2021 | Q18: 11:40:00 AM | R18: 5/6/2021 | S18: 9:47:00 PM | T18: 355 | U18: 4.6 | V18: 0.32 | W18: 0.7 | Z18: ACI measure at proccessing time. | AA18: 1498054 | AB18: 1629691 | AC18: =(AB18-AA18)/AB18 -> 0.080774208
A19: BML | B19: BML | C19: M. guttatus | E19: =INDEX(FieldSites!F:F, MATCH(Ch2_FieldSurvey!B19,FieldSites!C:C,0)) -> 1730 | F19: =INDEX(FieldSites!G:G, MATCH(Ch2_FieldSurvey!B19,FieldSites!C:C,0)) -> -119.31401 | G19: =INDEX(FieldSites!H:H, MATCH(Ch2_FieldSurvey!B19,FieldSites!C:C,0)) -> 37.090625 | H19: 4 | I19: BML_G4 | J19: 44321 | K19: 0.48611111 | L19: 44322 | M19: 0.90763889 | O19: BMLZ_G004 | P19: 5/5/2021 | Q19: 11:40:00 AM | R19: 5/6/2021 | S19: 9:47:00 PM | T19: 340 | U19: 4.4 | V19: 0.48 | W19: 0.5 | Z19: ACI measure at proccessing time.
A20: BML | B20: BML | C20: M. guttatus | E20: =INDEX(FieldSites!F:F, MATCH(Ch2_FieldSurvey!B20,FieldSites!C:C,0)) -> 1730 | F20: =INDEX(FieldSites!G:G, MATCH(Ch2_FieldSurvey!B20,FieldSites!C:C,0)) -> -119.31401 | G20: =INDEX(FieldSites!H:H, MATCH(Ch2_FieldSurvey!B20,FieldSites!C:C,0)) -> 37.090625 | H20: 4 | I20: BML_G4 | J20: 44321 | K20: 0.48611111 | L20: 44322 | M20: 0.90763889 | O20: BMLZ_G004 | P20: 5/5/2021 | Q20: 11:40:00 AM | R20: 5/6/2021 | S20: 9:47:00 PM | T20: 405 | U20: 4.3 | V20: 0.37 | W20: 0.7 | Z20: ACI measure at proccessing time.
A21: BML | B21: BML | C21: M. guttatus | E21: =INDEX(FieldSites!F:F, MATCH(Ch2_FieldSurvey!B21,FieldSites!C:C,0)) -> 1730 | F21: =INDEX(FieldSites!G:G, MATCH(Ch2_FieldSurvey!B21,FieldSites!C:C,0)) -> -119.31401 | G21: =INDEX(FieldSites!H:H, MATCH(Ch2_FieldSurvey!B21,FieldSites!C:C,0)) -> 37.090625 | H21: 5 | I21: BML_G5 | J21: 44321 | K21: 0.48958333 | L21: 44322 | M21: 0.90902778 | O21: BMLZ_G005 | P21: 5/5/2021 | Q21: 11:45:00 AM | R21: 5/6/2021 | S21: 9:49:00 PM | T21: 460 | U21: 4 | V21: 0.62 | W21: 0.8 | Z21: ACI measure at proccessing time. | AA21: 456220 | AB21: 506858 | AC21: =(AB21-AA21)/AB21 -> 0.099905694
A22: BML | B22: BML | C22: M. guttatus | E22: =INDEX(FieldSites!F:F, MATCH(Ch2_FieldSurvey!B22,FieldSites!C:C,0)) -> 1730 | F22: =INDEX(FieldSites!G:G, MATCH(Ch2_FieldSurvey!B22,FieldSites!C:C,0)) -> -119.31401 | G22: =INDEX(FieldSites!H:H, MATCH(Ch2_FieldSurvey!B22,FieldSites!C:C,0)) -> 37.090625 | H22: 5 | I22: BML_G5 | J22: 44321 | K22: 0.48958333 | L22: 44322 | M22: 0.90902778 | O22: BMLZ_G005 | P22: 5/5/2021 | Q22: 11:45:00 AM | R22: 5/6/2021 | S22: 9:49:00 PM | T22: 340 | U22: 4.2 | V22: 0.74 | W22: 1 | Z22: ACI measure at proccessing time.
A23: BML | B23: BML | C23: M. guttatus | E23: =INDEX(FieldSites!F:F, MATCH(Ch2_FieldSurvey!B23,FieldSites!C:C,0)) -> 1730 | F23: =INDEX(FieldSites!G:G, MATCH(Ch2_FieldSurvey!B23,FieldSites!C:C,0)) -> -119.31401 | G23: =INDEX(FieldSites!H:H, MATCH(Ch2_FieldSurvey!B23,FieldSites!C:C,0)) -> 37.090625 | H23: 5 | I23: BML_G5 | J23: 44321 | K23: 0.48958333 | L23: 44322 | M23: 0.90902778 | O23: BMLZ_G005 | P23: 5/5/2021 | Q23: 11:45:00 AM | R23: 5/6/2021 | S23: 9:49:00 PM | T23: 520 | U23: 4.5 | V23: 0.63 | W23: 0.9 | Z23: ACI measure at proccessing time.
A24: SHL | B24: SHL | C24: M. guttatus | E24: =INDEX(FieldSites!F:F, MATCH(Ch2_FieldSurvey!B24,FieldSites!C:C,0)) -> 1595 | F24: =INDEX(FieldSites!G:G, MATCH(Ch2_FieldSurvey!B24,FieldSites!C:C,0)) -> -119.30743 | G24: =INDEX(FieldSites!H:H, MATCH(Ch2_FieldSurvey!B24,FieldSites!C:C,0)) -> 37.145131 | H24: 1 | I24: SHL_G1 | J24: 44321 | K24: 0.52708333 | L24: 44322 | M24: 0.9125 | O24: SHLZ_G001 | P24: 5/5/2021 | Q24: 12:39:00 PM | R24: 5/6/2021 | S24: 9:54:00 PM | T24: 264 | U24: 4.2 | V24: 0.63 | W24: 1.1 | Z24: ACI measure at proccessing time. | AA24: 582646 | AB24: 621722 | AC24: =(AB24-AA24)/AB24 -> 0.062851242
A25: SHL | B25: SHL | C25: M. guttatus | E25: =INDEX(FieldSites!F:F, MATCH(Ch2_FieldSurvey!B25,FieldSites!C:C,0)) -> 1595 | F25: =INDEX(FieldSites!G:G, MATCH(Ch2_FieldSurvey!B25,FieldSites!C:C,0)) -> -119.30743 | G25: =INDEX(FieldSites!H:H, MATCH(Ch2_FieldSurvey!B25,FieldSites!C:C,0)) -> 37.145131 | H25: 1 | I25: SHL_G1 | J25: 44321 | K25: 0.52708333 | L25: 44322 | M25: 0.9125 | O25: SHLZ_G001 | P25: 5/5/2021 | Q25: 12:39:00 PM | R25: 5/6/2021 | S25: 9:54:00 PM | T25: 265 | U25: 4.3 | V25: 0.52 | W25: 1.1 | Z25: ACI measure at proccessing time.
A26: SHL | B26: SHL | C26: M. guttatus | E26: =INDEX(FieldSites!F:F, MATCH(Ch2_FieldSurvey!B26,FieldSites!C:C,0)) -> 1595 | F26: =INDEX(FieldSites!G:G, MATCH(Ch2_FieldSurvey!B26,FieldSites!C:C,0)) -> -119.30743 | G26: =INDEX(FieldSites!H:H, MATCH(Ch2_FieldSurvey!B26,FieldSites!C:C,0)) -> 37.145131 | H26: 1 | I26: SHL_G1 | J26: 44321 | K26: 0.52708333 | L26: 44322 | M26: 0.9125 | O26: SHLZ_G001 | P26: 5/5/2021 | Q26: 12:39:00 PM | R26: 5/6/2021 | S26: 9:54:00 PM | T26: 355 | U26: 3.8 | V26: 0.44 | W26: 1.1 | Z26: ACI measure at proccessing time.
A27: SHL | B27: SHL | C27: M. guttatus | E27: =INDEX(FieldSites!F:F, MATCH(Ch2_FieldSurvey!B27,FieldSites!C:C,0)) -> 1595 | F27: =INDEX(FieldSites!G:G, MATCH(Ch2_FieldSurvey!B27,FieldSites!C:C,0)) -> -119.30743 | G27: =INDEX(FieldSites!H:H, MATCH(Ch2_FieldSurvey!B27,FieldSites!C:C,0)) -> 37.145131 | H27: 2 | I27: SHL_G2 | J27: 44321 | K27: 0.52777778 | L27: 44322 | M27: 0.91458333 | O27: SHLZ_G002 | P27: 5/5/2021 | Q27: 12:40:00 PM | R27: 5/6/2021 | S27: 9:57:00 PM | T27: 520 | U27: 5.6 | V27: 0.51 | W27: 0.5 | Z27: ACI measure at proccessing time. | AA27: 1298732 | AB27: 1407504 | AC27: =(AB27-AA27)/AB27 -> 0.077280065
A28: SHL | B28: SHL | C28: M. guttatus | E28: =INDEX(FieldSites!F:F, MATCH(Ch2_FieldSurvey!B28,FieldSites!C:C,0)) -> 1595 | F28: =INDEX(FieldSites!G:G, MATCH(Ch2_FieldSurvey!B28,FieldSites!C:C,0)) -> -119.30743 | G28: =INDEX(FieldSites!H:H, MATCH(Ch2_FieldSurvey!B28,FieldSites!C:C,0)) -> 37.145131 | H28: 2 | I28: SHL_G2 | J28: 44321 | K28: 0.52777778 | L28: 44322 | M28: 0.91458333 | O28: SHLZ_G002 | P28: 5/5/2021 | Q28: 12:40:00 PM | R28: 5/6/2021 | S28: 9:57:00 PM | T28: 530 | U28: 4.4 | V28: 0.54 | W28: 0.4 | Z28: ACI measure at proccessing time.
A29: SHL | B29: SHL | C29: M. guttatus | E29: =INDEX(FieldSites!F:F, MATCH(Ch2_FieldSurvey!B29,FieldSites!C:C,0)) -> 1595 | F29: =INDEX(FieldSites!G:G, MATCH(Ch2_FieldSurvey!B29,FieldSites!C:C,0)) -> -119.30743 | G29: =INDEX(FieldSites!H:H, MATCH(Ch2_FieldSurvey!B29,FieldSites!C:C,0)) -> 37.145131 | H29: 2 | I29: SHL_G2 | J29: 44321 | K29: 0.52777778 | L29: 44322 | M29: 0.91458333 | O29: SHLZ_G002 | P29: 5/5/2021 | Q29: 12:40:00 PM | R29: 5/6/2021 | S29: 9:57:00 PM | T29: 430 | U29: 4.4 | V29: 0.55 | W29: 0.3 | Z29: ACI measure at proccessing time.
A30: SHL | B30: SHL | C30: M. guttatus | E30: =INDEX(FieldSites!F:F, MATCH(Ch2_FieldSurvey!B30,FieldSites!C:C,0)) -> 1595 | F30: =INDEX(FieldSites!G:G, MATCH(Ch2_FieldSurvey!B30,FieldSites!C:C,0)) -> -119.30743 | G30: =INDEX(FieldSites!H:H, MATCH(Ch2_FieldSurvey!B30,FieldSites!C:C,0)) -> 37.145131 | H30: 3 | I30: SHL_G3 | J30: 44321 | K30: 0.53125 | L30: 44322 | M30: 0.91666667 | O30: SHLZ_G003 | P30: 5/5/2021 | Q30: 12:45:00 PM | R30: 5/6/2021 | S30: 10:00:00 PM | T30: 240 | U30: 3 | V30: 0.38 | W30: 0.5 | Z30: ACI measure at proccessing time. | AA30: 1703397 | AB30: 1808854 | AC30: =(AB30-AA30)/AB30 -> 0.058300449
A31: SHL | B31: SHL | C31: M. guttatus | E31: =INDEX(FieldSites!F:F, MATCH(Ch2_FieldSurvey!B31,FieldSites!C:C,0)) -> 1595 | F31: =INDEX(FieldSites!G:G, MATCH(Ch2_FieldSurvey!B31,FieldSites!C:C,0)) -> -119.30743 | G31: =INDEX(FieldSites!H:H, MATCH(Ch2_FieldSurvey!B31,FieldSites!C:C,0)) -> 37.145131 | H31: 3 | I31: SHL_G3 | J31: 44321 | K31: 0.53125 | L31: 44322 | M31: 0.91666667 | O31: SHLZ_G003 | P31: 5/5/2021 | Q31: 12:45:00 PM | R31: 5/6/2021 | S31: 10:00:00 PM | T31: 335 | U31: 3 | V31: 0.34 | W31: 0.5 | Z31: ACI measure at proccessing time.
A32: SHL | B32: SHL | C32: M. guttatus | E32: =INDEX(FieldSites!F:F, MATCH(Ch2_FieldSurvey!B32,FieldSites!C:C,0)) -> 1595 | F32: =INDEX(FieldSites!G:G, MATCH(Ch2_FieldSurvey!B32,FieldSites!C:C,0)) -> -119.30743 | G32: =INDEX(FieldSites!H:H, MATCH(Ch2_FieldSurvey!B32,FieldSites!C:C,0)) -> 37.145131 | H32: 3 | I32: SHL_G3 | J32: 44321 | K32: 0.53125 | L32: 44322 | M32: 0.91666667 | O32: SHLZ_G003 | P32: 5/5/2021 | Q32: 12:45:00 PM | R32: 5/6/2021 | S32: 10:00:00 PM | T32: 400 | U32: 3.4 | V32: 0.38 | W32: 0.7 | Z32: ACI measure at proccessing time.
A33: SHL | B33: SHL | C33: M. guttatus | E33: =INDEX(FieldSites!F:F, MATCH(Ch2_FieldSurvey!B33,FieldSites!C:C,0)) -> 1595 | F33: =INDEX(FieldSites!G:G, MATCH(Ch2_FieldSurvey!B33,FieldSites!C:C,0)) -> -119.30743 | G33: =INDEX(FieldSites!H:H, MATCH(Ch2_FieldSurvey!B33,FieldSites!C:C,0)) -> 37.145131 | H33: 4 | I33: SHL_G4 | J33: 44321 | K33: 0.53472222 | L33: 44322 | M33: 0.91875 | O33: SHLZ_G004 | P33: 5/5/2021 | Q33: 12:50:00 PM | R33: 5/6/2021 | S33: 10:03:00 PM | T33: 324 | U33: 3.6 | V33: 0.38 | W33: 0.6 | Z33: ACI measure at proccessing time. | AA33: 682923 | AB33: 720876 | AC33: =(AB33-AA33)/AB33 -> 0.052648444
A34: SHL | B34: SHL | C34: M. guttatus | E34: =INDEX(FieldSites!F:F, MATCH(Ch2_FieldSurvey!B34,FieldSites!C:C,0)) -> 1595 | F34: =INDEX(FieldSites!G:G, MATCH(Ch2_FieldSurvey!B34,FieldSites!C:C,0)) -> -119.30743 | G34: =INDEX(FieldSites!H:H, MATCH(Ch2_FieldSurvey!B34,FieldSites!C:C,0)) -> 37.145131 | H34: 4 | I34: SHL_G4 | J34: 44321 | K34: 0.53472222 | L34: 44322 | M34: 0.91875 | O34: SHLZ_G004 | P34: 5/5/2021 | Q34: 12:50:00 PM | R34: 5/6/2021 | S34: 10:03:00 PM | T34: 395 | U34: 4.1 | V34: 0.38 | W34: 0.6 | Z34: ACI measure at proccessing time.
A35: SHL | B35: SHL | C35: M. guttatus | E35: =INDEX(FieldSites!F:F, MATCH(Ch2_FieldSurvey!B35,FieldSites!C:C,0)) -> 1595 | F35: =INDEX(FieldSites!G:G, MATCH(Ch2_FieldSurvey!B35,FieldSites!C:C,0)) -> -119.30743 | G35: =INDEX(FieldSites!H:H, MATCH(Ch2_FieldSurvey!B35,FieldSites!C:C,0)) -> 37.145131 | H35: 4 | I35: SHL_G4 | J35: 44321 | K35: 0.53472222 | L35: 44322 | M35: 0.91875 | O35: SHLZ_G004 | P35: 5/5/2021 | Q35: 12:50:00 PM | R35: 5/6/2021 | S35: 10:03:00 PM | T35: 510 | U35: 4 | V35: 0.39 | W35: 0.8 | Z35: ACI measure at proccessing time.
A36: SHL | B36: SHL | C36: M. guttatus | D36: Y | E36: =INDEX(FieldSites!F:F, MATCH(Ch2_FieldSurvey!B36,FieldSites!C:C,0)) -> 1595 | F36: =INDEX(FieldSites!G:G, MATCH(Ch2_FieldSurvey!B36,FieldSites!C:C,0)) -> -119.30743 | G36: =INDEX(FieldSites!H:H, MATCH(Ch2_FieldSurvey!B36,FieldSites!C:C,0)) -> 37.145131 | H36: 5 | I36: SHL_G5 | J36: 44321 | K36: 0.54166667 | L36: 44322 | M36: 0.92152778 | O36: SHLZ_G005 | P36: 5/5/2021 | Q36: 1:00:00 PM | R36: 5/6/2021 | S36: 10:07:00 PM | T36: 510 | U36: 4.6 | V36: 0.43 | W36: 0.6 | Z36: ACI measure at proccessing time. | AA36: 829159 | AB36: 1023402 | AC36: =(AB36-AA36)/AB36 -> 0.18980127
A37: SHL | B37: SHL | C37: M. guttatus | D37: Y | E37: =INDEX(FieldSites!F:F, MATCH(Ch2_FieldSurvey!B37,FieldSites!C:C,0)) -> 1595 | F37: =INDEX(FieldSites!G:G, MATCH(Ch2_FieldSurvey!B37,FieldSites!C:C,0)) -> -119.30743 | G37: =INDEX(FieldSites!H:H, MATCH(Ch2_FieldSurvey!B37,FieldSites!C:C,0)) -> 37.145131 | H37: 5 | I37: SHL_G5 | J37: 44321 | K37: 0.54166667 | L37: 44322 | M37: 0.92152778 | O37: SHLZ_G005 | P37: 5/5/2021 | Q37: 1:00:00 PM | R37: 5/6/2021 | S37: 10:07:00 PM | T37: 430 | U37: 4.6 | V37: 0.46 | W37: 0.5 | Z37: ACI measure at proccessing time.
A38: SHL | B38: SHL | C38: M. guttatus | D38: Y | E38: =INDEX(FieldSites!F:F, MATCH(Ch2_FieldSurvey!B38,FieldSites!C:C,0)) -> 1595 | F38: =INDEX(FieldSites!G:G, MATCH(Ch2_FieldSurvey!B38,FieldSites!C:C,0)) -> -119.30743 | G38: =INDEX(FieldSites!H:H, MATCH(Ch2_FieldSurvey!B38,FieldSites!C:C,0)) -> 37.145131 | H38: 5 | I38: SHL_G5 | J38: 44321 | K38: 0.54166667 | L38: 44322 | M38: 0.92152778 | O38: SHLZ_G005 | P38: 5/5/2021 | Q38: 1:00:00 PM | R38: 5/6/2021 | S38: 10:07:00 PM | T38: 505 | U38: 4.7 | V38: 0.55 | W38: 0.8 | Z38: ACI measure at proccessing time.
A39: SHL | B39: SHL | C39: M. laciniatus | E39: =INDEX(FieldSites!F:F, MATCH(Ch2_FieldSurvey!B39,FieldSites!C:C,0)) -> 1595 | F39: =INDEX(FieldSites!G:G, MATCH(Ch2_FieldSurvey!B39,FieldSites!C:C,0)) -> -119.30743 | G39: =INDEX(FieldSites!H:H, MATCH(Ch2_FieldSurvey!B39,FieldSites!C:C,0)) -> 37.145131 | H39: 1 | I39: SHL_L1 | J39: 44321 | K39: 0.54166667 | L39: 44322 | M39: 0.93819444 | O39: SHLZ_L001 | P39: 5/5/2021 | Q39: 1:00:00 PM | R39: 5/6/2021 | S39: 10:31:00 PM | T39: 415 | U39: 3.1 | V39: 0.41 | W39: 0.4 | Z39: ACI measure at proccessing time. | AA39: 135431 | AB39: 181589 | AC39: =(AB39-AA39)/AB39 -> 0.25418941
A40: SHL | B40: SHL | C40: M. laciniatus | E40: =INDEX(FieldSites!F:F, MATCH(Ch2_FieldSurvey!B40,FieldSites!C:C,0)) -> 1595 | F40: =INDEX(FieldSites!G:G, MATCH(Ch2_FieldSurvey!B40,FieldSites!C:C,0)) -> -119.30743 | G40: =INDEX(FieldSites!H:H, MATCH(Ch2_FieldSurvey!B40,FieldSites!C:C,0)) -> 37.145131 | H40: 1 | I40: SHL_L1 | J40: 44321 | K40: 0.54166667 | L40: 44322 | M40: 0.93819444 | O40: SHLZ_L001 | P40: 5/5/2021 | Q40: 1:00:00 PM | R40: 5/6/2021 | S40: 10:31:00 PM | T40: 415 | U40: 2.4 | V40: 0.34 | Z40: ACI measure at proccessing time.
...

Sheet FieldSites
A1: Site_name | B1: Forest_Park | C1: Population | D1: Unique_ID | E1: Elevation_ft | F1: Elevation_m | G1: Longitude | H1: Latitude | I1: #M.laciniatus | J1: #M.guttatus | K1: #M.nasutus | L1: #M.bicolor | M1: Sympatric(Y/N) | N1: Notes
A2: Bretz Mill Road | B2: Sierra_National_Forest | C2: BML | D2: BMLZ | E2: 5643 | F2: =INDEX(FieldSites!C$34:C$100, MATCH(FieldSites!C2, FieldSites!H$34:H$100,0)) -> 1730 | G2: =INDEX(FieldSites!A$34:A$100, MATCH(FieldSites!C2, FieldSites!H$34:H$100,0)) -> -119.31401 | H2: =INDEX(FieldSites!B$34:B$100, MATCH(FieldSites!C2, FieldSites!H$34:H$100,0)) -> 37.090625 | I2: 5 | J2: 5 | K2: 0 | L2: 0 | M2: Y | N2: *aka: BML2019
A3: Shaver Lake | B3: Sierra_National_Forest | C3: SHL | D3: SHLZ | E3: 5233 | F3: =INDEX(FieldSites!C$34:C$100, MATCH(FieldSites!C3, FieldSites!H$34:H$100,0)) -> 1595 | G3: =INDEX(FieldSites!A$34:A$100, MATCH(FieldSites!C3, FieldSites!H$34:H$100,0)) -> -119.30743 | H3: =INDEX(FieldSites!B$34:B$100, MATCH(FieldSites!C3, FieldSites!H$34:H$100,0)) -> 37.145131 | I3: 5 | J3: 5 | K3: 0 | L3: 0 | M3: Y | N3: *aka: SHL2019
B4: Yosemite_National_Park | C4: FVWB | D4: FVWB | E4: 5766 | F4: =INDEX(FieldSites!C$34:C$100, MATCH(FieldSites!C4, FieldSites!H$34:H$100,0)) -> 1757 | G4: =INDEX(FieldSites!A$34:A$100, MATCH(FieldSites!C4, FieldSites!H$34:H$100,0)) -> -119.70272 | H4: =INDEX(FieldSites!B$34:B$100, MATCH(FieldSites!C4, FieldSites!H$34:H$100,0)) -> 37.698587 | I4: 1 | J4: 1 | K4: 0 | L4: 0 | M4: N
A5: Lower Yosemite Falls Trail | B5: Yosemite_National_Park | C5: LYFB | D5: LYFB | E5: 5203 | F5: =INDEX(FieldSites!C$34:C$100, MATCH(FieldSites!C5, FieldSites!H$34:H$100,0)) -> 1565 | G5: =INDEX(FieldSites!A$34:A$100, MATCH(FieldSites!C5, FieldSites!H$34:H$100,0)) -> -119.60139 | H5: =INDEX(FieldSites!B$34:B$100, MATCH(FieldSites!C5, FieldSites!H$34:H$100,0)) -> 37.748823 | I5: 0 | J5: 5 | K5: 0 | L5: 0 | M5: N
A6: Huntington Lake Overview | B6: Sierra_National_Forest | C6: HUOB | D6: HUOB | E6: 6033 | F6: =INDEX(FieldSites!C$34:C$100, MATCH(FieldSites!C6, FieldSites!H$34:H$100,0)) -> 1851 | G6: =INDEX(FieldSites!A$34:A$100, MATCH(FieldSites!C6, FieldSites!H$34:H$100,0)) -> -119.27351 | H6: =INDEX(FieldSites!B$34:B$100, MATCH(FieldSites!C6, FieldSites!H$34:H$100,0)) -> 37.150723 | I6: 0 | J6: 17 | K6: 5 | L6: 0 | M6: Y | O6: SUMMARY TABLE | P6: Population | Q6: Elevation | R6: #M.laciniatus | S6: #M.guttatus | T6: #M.nasutus | U6: #M.bicolor | V6: Sympatric(Y/N)
A7: Huntington Lake | B7: Sierra_National_Forest | C7: HULB | D7: HULB | E7: 7126 | F7: =INDEX(FieldSites!C$34:C$100, MATCH(FieldSites!C7, FieldSites!H$34:H$100,0)) -> 2178 | G7: =INDEX(FieldSites!A$34:A$100, MATCH(FieldSites!C7, FieldSites!H$34:H$100,0)) -> -119.14962 | H7: =INDEX(FieldSites!B$34:B$100, MATCH(FieldSites!C7, FieldSites!H$34:H$100,0)) -> 37.23553 | I7: 5 | J7: 5 | K7: 0 | L7: 0 | M7: Y | O7: MIN | Q7: =MIN(E2:E27) -> 2081 | R7: =MIN(I2:I27) -> 0 | S7: =MIN(J2:J27) -> 0 | T7: =MIN(K2:K27) -> 0 | U7: =MIN(L2:L27) -> 0
A8: Little Meadow | B8: Yosemite_National_Park | C8: LM | D8: LMZZ | E8: 6250 | F8: =INDEX(FieldSites!C$34:C$100, MATCH(FieldSites!C8, FieldSites!H$34:H$100,0)) -> 2157 | G8: =INDEX(FieldSites!A$34:A$100, MATCH(FieldSites!C8, FieldSites!H$34:H$100,0)) -> -119.77272 | H8: =INDEX(FieldSites!B$34:B$100, MATCH(FieldSites!C8, FieldSites!H$34:H$100,0)) -> 37.767781 | I8: 0 | J8: 10 | K8: 0 | L8: 0 | M8: N | O8: MAX | Q8: =MAX(E2:E27) -> 8442 | R8: =MAX(I2:I27) -> 20 | S8: =MAX(J2:J27) -> 17 | T8: =MAX(K2:K27) -> 11 | U8: =MAX(L2:L27) -> 10
A9: Crane Flat | B9: Yosemite_National_Park | C9: CF | D9: CFZZ | E9: 6237 | F9: =INDEX(FieldSites!C$34:C$100, MATCH(FieldSites!C9, FieldSites!H$34:H$100,0)) -> 1901 | G9: =INDEX(FieldSites!A$34:A$100, MATCH(FieldSites!C9, FieldSites!H$34:H$100,0)) -> -119.80295 | H9: =INDEX(FieldSites!B$34:B$100, MATCH(FieldSites!C9, FieldSites!H$34:H$100,0)) -> 37.755986 | I9: 0 | J9: 10 | K9: 0 | L9: 0 | M9: N | O9: TOTAL per Species | R9: =SUM(I2:I27) -> 121 | S9: =SUM(J2:J27) -> 143 | T9: =SUM(K2:K27) -> 46 | U9: =SUM(L2:L27) -> 14 | V9: 13(N) 11(Y)
A10: Angel Falls | B10: Sierra_National_Forest | C10: AGFB | D10: AGFB | E10: 3688 | F10: =INDEX(FieldSites!C$34:C$100, MATCH(FieldSites!C10, FieldSites!H$34:H$100,0)) -> 1124 | G10: =INDEX(FieldSites!A$34:A$100, MATCH(FieldSites!C10, FieldSites!H$34:H$100,0)) -> -119.57068 | H10: =INDEX(FieldSites!B$34:B$100, MATCH(FieldSites!C10, FieldSites!H$34:H$100,0)) -> 37.33823 | I10: 10 | J10: 0 | K10: 10 | L10: 0 | M10: Y | O10: TOTAL # sites | P10: =COUNTA(C2:C27) -> 26
A11: Bald Mountain | B11: Sierra_National_Forest | C11: BHEB | D11: BHEB | E11: 3967 | F11: =INDEX(FieldSites!C$34:C$100, MATCH(FieldSites!C11, FieldSites!H$34:H$100,0)) -> 1209 | G11: =INDEX(FieldSites!A$34:A$100, MATCH(FieldSites!C11, FieldSites!H$34:H$100,0)) -> -119.39323 | H11: =INDEX(FieldSites!B$34:B$100, MATCH(FieldSites!C11, FieldSites!H$34:H$100,0)) -> 37.053544 | I11: 0 | J11: 10 | K11: 10 | L11: 0 | M11: Y | O11: TOTAL | P11: =SUM(R9:U9) -> 324
A12: Hetch Hetchy B | B12: Yosemite_National_Park | C12: HHBB | D12: HHBB | E12: 3934 | F12: =INDEX(FieldSites!C$34:C$100, MATCH(FieldSites!C12, FieldSites!H$34:H$100,0)) -> 1199 | G12: =INDEX(FieldSites!A$34:A$100, MATCH(FieldSites!C12, FieldSites!H$34:H$100,0)) -> -119.77855 | H12: =INDEX(FieldSites!B$34:B$100, MATCH(FieldSites!C12, FieldSites!H$34:H$100,0)) -> 37.959056 | I12: 10 | J12: 10 | K12: 0 | L12: 0 | M12: Y
A13: Turtle Back Dome B | B13: Yosemite_National_Park | C13: TRTB | D13: TRTB | E13: 5158 | F13: =INDEX(FieldSites!C$34:C$100, MATCH(FieldSites!C13, FieldSites!H$34:H$100,0)) -> 1572 | G13: =INDEX(FieldSites!A$34:A$100, MATCH(FieldSites!C13, FieldSites!H$34:H$100,0)) -> -119.71015 | H13: =INDEX(FieldSites!B$34:B$100, MATCH(FieldSites!C13, FieldSites!H$34:H$100,0)) -> 37.700419 | I13: 1 | J13: 0 | L13: 0 | M13: N
A14: Turtle Back Dome | B14: Yosemite_National_Park | C14: TRT | D14: TRTZ | E14: 4875 | F14: =INDEX(FieldSites!C$34:C$100, MATCH(FieldSites!C14, FieldSites!H$34:H$100,0)) -> 1486 | G14: =INDEX(FieldSites!A$34:A$100, MATCH(FieldSites!C14, FieldSites!H$34:H$100,0)) -> -119.70532 | H14: =INDEX(FieldSites!B$34:B$100, MATCH(FieldSites!C14, FieldSites!H$34:H$100,0)) -> 37.716098 | I14: 10 | J14: 0 | K14: 0 | L14: 0 | M14: N | N14: * aka: TRT2019
A15: Tawonga | B15: Stanislaus_National_Forest | C15: TWGB | D15: TWGB | E15: 4793 | F15: =INDEX(FieldSites!C$34:C$100, MATCH(FieldSites!C15, FieldSites!H$34:H$100,0)) -> 1238 | G15: =INDEX(FieldSites!A$34:A$100, MATCH(FieldSites!C15, FieldSites!H$34:H$100,0)) -> -119.95131 | H15: =INDEX(FieldSites!B$34:B$100, MATCH(FieldSites!C15, FieldSites!H$34:H$100,0)) -> 37.85882 | I15: 0 | J15: 10 | K15: 0 | L15: 0 | M15: N
A16: Carson Creek | B16: Mariposa County | C16: CCRB | D16: CCRB | E16: 2081 | F16: =INDEX(FieldSites!C$34:C$100, MATCH(FieldSites!C16, FieldSites!H$34:H$100,0)) -> 666 | G16: =INDEX(FieldSites!A$34:A$100, MATCH(FieldSites!C16, FieldSites!H$34:H$100,0)) -> -119.99792 | H16: =INDEX(FieldSites!B$34:B$100, MATCH(FieldSites!C16, FieldSites!H$34:H$100,0)) -> 37.486337 | I16: 0 | J16: 0 | K16: 10 | L16: 0 | M16: N
A17: North Fork Willow Creek | B17: Sierra_National_Forest | C17: NFWB | D17: NFWB | E17: 2772 | F17: =INDEX(FieldSites!C$34:C$100, MATCH(FieldSites!C17, FieldSites!H$34:H$100,0)) -> 875 | G17: =INDEX(FieldSites!A$34:A$100, MATCH(FieldSites!C17, FieldSites!H$34:H$100,0)) -> -119.52142 | H17: =INDEX(FieldSites!B$34:B$100, MATCH(FieldSites!C17, FieldSites!H$34:H$100,0)) -> 37.257397 | I17: 7 | J17: 0 | K17: 11 | L17: 0 | M17: Y
A18: Wildcat Falls | B18: Yosemite_National_Park | C18: WCFB | D18: WCFB | E18: 4528 | F18: =INDEX(FieldSites!C$34:C$100, MATCH(FieldSites!C18, FieldSites!H$34:H$100,0)) -> 1380 | G18: =INDEX(FieldSites!A$34:A$100, MATCH(FieldSites!C18, FieldSites!H$34:H$100,0)) -> -119.71908 | H18: =INDEX(FieldSites!B$34:B$100, MATCH(FieldSites!C18, FieldSites!H$34:H$100,0)) -> 37.723593 | I18: 11 | J18: 12 | K18: 0 | L18: 0 | M18: Y
A19: Highland Drive Road | B19: Sierra_National_Forest | C19: HDRB | D19: HDRB | E19: 3284 | F19: =INDEX(FieldSites!C$34:C$100, MATCH(FieldSites!C19, FieldSites!H$34:H$100,0)) -> 1037 | G19: =INDEX(FieldSites!A$34:A$100, MATCH(FieldSites!C19, FieldSites!H$34:H$100,0)) -> -119.53471 | H19: =INDEX(FieldSites!B$34:B$100, MATCH(FieldSites!C19, FieldSites!H$34:H$100,0)) -> 37.288671 | I19: 0 | J19: 10 | K19: 0 | L19: 0 | M19: N
A20: Stoddard Spring | B20: Stanislaus_National_Forest | C20: SDSB | D20: SDSB | E20: 5511 | F20: =INDEX(FieldSites!C$34:C$100, MATCH(FieldSites!C20, FieldSites!H$34:H$100,0)) -> 1679 | G20: =INDEX(FieldSites!A$34:A$100, MATCH(FieldSites!C20, FieldSites!H$34:H$100,0)) -> -120.09461 | H20: =INDEX(FieldSites!B$34:B$100, MATCH(FieldSites!C20, FieldSites!H$34:H$100,0)) -> 38.136194 | I20: 0 | J20: 10 | K20: 0 | L20: 10 | M20: Y
A21: Crab Tree Road | B21: Stanislaus_National_Forest | C21: CCNB | D21: CCNB | E21: 6554 | F21: =INDEX(FieldSites!C$34:C$100, MATCH(FieldSites!C21, FieldSites!H$34:H$100,0)) -> 1997 | G21: =INDEX(FieldSites!A$34:A$100, MATCH(FieldSites!C21, FieldSites!H$34:H$100,0)) -> -119.96325 | H21: =INDEX(FieldSites!B$34:B$100, MATCH(FieldSites!C21, FieldSites!H$34:H$100,0)) -> 38.183927 | I21: 0 | J21: 12 | K21: 0 | L21: 4 | M21: Y
A22: Wawona School | B22: Yosemite_National_Park | C22: WSHB | D22: WSHB | E22: 4055 | F22: =INDEX(FieldSites!C$34:C$100, MATCH(FieldSites!C22, FieldSites!H$34:H$100,0)) -> 1235 | G22: =INDEX(FieldSites!A$34:A$100, MATCH(FieldSites!C22, FieldSites!H$34:H$100,0)) -> -119.64788 | H22: =INDEX(FieldSites!B$34:B$100, MATCH(FieldSites!C22, FieldSites!H$34:H$100,0)) -> 37.543343 | I22: 0 | J22: 11 | K22: 0 | L22: 0 | M22: N
A23: Onion Skins | B23: Yosemite_National_Park | C23: OSKB | D23: OSKB | E23: 7808 | F23: =INDEX(FieldSites!C$34:C$100, MATCH(FieldSites!C23, FieldSites!H$34:H$100,0)) -> 2399 | G23: =INDEX(FieldSites!A$34:A$100, MATCH(FieldSites!C23, FieldSites!H$34:H$100,0)) -> -119.59457 | H23: =INDEX(FieldSites!B$34:B$100, MATCH(FieldSites!C23, FieldSites!H$34:H$100,0)) -> 37.842693 | I23: 7 | J23: 0 | K23: 0 | L23: 0 | M23: N
A24: Spotless | B24: Yosemite_National_Park | C24: SPLB | D24: SPLB | E24: 8281 | F24: =INDEX(FieldSites!C$34:C$100, MATCH(FieldSites!C24, FieldSites!H$34:H$100,0)) -> 2348 | G24: =INDEX(FieldSites!A$34:A$100, MATCH(FieldSites!C24, FieldSites!H$34:H$100,0)) -> -119.58613 | H24: =INDEX(FieldSites!B$34:B$100, MATCH(FieldSites!C24, FieldSites!H$34:H$100,0)) -> 37.847194 | I24: 9 | J24: 0 | K24: 0 | L24: 0 | M24: N
A25: Yosemite Creek B | B25: Yosemite_National_Park | C25: YCNB | D25: YCNB | E25: 7736 | F25: =INDEX(FieldSites!C$34:C$100, MATCH(FieldSites!C25, FieldSites!H$34:H$100,0)) -> 2357 | G25: =INDEX(FieldSites!A$34:A$100, MATCH(FieldSites!C25, FieldSites!H$34:H$100,0)) -> -119.57275 | H25: =INDEX(FieldSites!B$34:B$100, MATCH(FieldSites!C25, FieldSites!H$34:H$100,0)) -> 37.843904 | I25: 10 | J25: 0 | K25: 0 | L25: 0 | M25: N
A26: The Knobs | B26: Yosemite_National_Park | C26: KNOB | D26: KNOB | E26: 8442 | F26: =INDEX(FieldSites!C$34:C$100, MATCH(FieldSites!C26, FieldSites!H$34:H$100,0)) -> 2572 | G26: =INDEX(FieldSites!A$34:A$100, MATCH(FieldSites!C26, FieldSites!H$34:H$100,0)) -> -119.44037 | H26: =INDEX(FieldSites!B$34:B$100, MATCH(FieldSites!C26, FieldSites!H$34:H$100,0)) -> 37.853852 | I26: 10 | J26: 0 | K26: 0 | L26: 0 | M26: N
A27: Olmstead Point | B27: Yosemite_National_Park | C27: OPN | D27: OPNZ | E27: 8225 | F27: =INDEX(FieldSites!C$34:C$100, MATCH(FieldSites!C27, FieldSites!H$34:H$100,0)) -> 2506 | G27: =INDEX(FieldSites!A$34:A$100, MATCH(FieldSites!C27, FieldSites!H$34:H$100,0)) -> -119.48631 | H27: =INDEX(FieldSites!B$34:B$100, MATCH(FieldSites!C27, FieldSites!H$34:H$100,0)) -> 37.807232 | I27: 20 | J27: 0 | K27: 0 | L27: 0 | M27: N
D28: * The letter Z is used as a place holder for population == Unique_ID or Sample_ID
A32: GPS_metadata
A33: X | B33: Y | C33: ele | E33: time | F33: magvar | G33: geoidheight | H33: name | I33: cmt | J33: desc
A34: -119.59457 | B34: 37.842693 | C34: 2399 | E34: 2022/06/02 19:20:56+00 | H34: OSKB | J34: Onion Skinning site. Roadside M. laciniatus population. Highly lobed.
A35: -119.71868 | B35: 37.723542 | C35: 1372 | E35: 2019/05/10 16:37:02+00 | H35: TNL2019 | J35: M. Nasutus and M. Laciniatus and some other Mimulus sp.
A36: -119.7814 | B36: 37.958448 | C36: 1202 | E36: 2022/04/20 18:35:08+00 | H36: HHAB
A37: -119.5957 | B37: 37.8264 | C37: 2203 | E37: 2019/04/19 18:32:40+00 | H37: YCN | J37: M. laciniatus reported; genotype: 6, 11, 12, 13, and 15.
A38: -119.94875 | B38: 37.865012 | C38: 1237 | E38: 2022/05/02 22:31:28+00 | H38: MDWB | J38: Mini Meadow. M. guttatus population in recovering meadow. The center of the population is a sweat bee nest.
A39: -119.63442 | B39: 37.486651 | C39: 1516 | E39: 2022/04/30 04:28:36+00 | H39: SMDB
A40: -120.09461 | B40: 38.136194 | C40: 1679 | E40: 2022/05/21 21:50:11+00 | H40: SDSB | J40: Stoddard Spring. Stanislaus Nat'l Forest. Left hand side of the road towards Pincrest on road 108. Mimulus guttatus and Mimulus bicolor on granite outcrop and granite sand.
A41: -119.30743 | B41: 37.145131 | C41: 1595 | E41: 2019/05/30 23:59:22+00 | H41: SHL | I41: SHL2019 | J41: Easily accesible. Found M. nasutus, M. laciniatus amd M. bicolor on site. Some specimens appear to be hybrids between M. laciniatus and M. guttatus. This is what N. Gonzales calls SHL hybrids in the Ferris lab.
A42: -119.48631 | B42: 37.807232 | C42: 2506 | E42: 2019/04/19 18:32:40+00 | H42: OPN | J42: no data
A43: -119.71178 | B43: 37.701819 | C43: 1533 | E43: 2019/05/10 17:40:26+00 | H43: STD2019
...

Sheet clean_site_lat_long
A1: Site_name | B1: Forest_Park | C1: Population | D1: Unique_ID | E1: Elevation_ft | F1: Elevation_m | G1: Longitude | H1: Latitude | I1: M.laciniatus | J1: M.guttatus | K1: M.nasutus | L1: M.bicolor | M1: Sympatric | N1: Notes
A2: Bretz Mill Road | B2: Sierra_National_Forest | C2: BML | D2: BMLZ | E2: 5643 | F2: =INDEX(FieldSites!C$34:C$100, MATCH(FieldSites!C2, FieldSites!H$34:H$100,0)) -> 1730 | G2: =INDEX(FieldSites!A$34:A$100, MATCH(FieldSites!C2, FieldSites!H$34:H$100,0)) -> -119.31401 | H2: =INDEX(FieldSites!B$34:B$100, MATCH(FieldSites!C2, FieldSites!H$34:H$100,0)) -> 37.090625 | I2: 5 | J2: 5 | K2: 0 | L2: 0 | M2: Y | N2: *aka: BML2019
A3: Shaver Lake | B3: Sierra_National_Forest | C3: SHL | D3: SHLZ | E3: 5233 | F3: =INDEX(FieldSites!C$34:C$100, MATCH(FieldSites!C3, FieldSites!H$34:H$100,0)) -> 1595 | G3: =INDEX(FieldSites!A$34:A$100, MATCH(FieldSites!C3, FieldSites!H$34:H$100,0)) -> -119.30743 | H3: =INDEX(FieldSites!B$34:B$100, MATCH(FieldSites!C3, FieldSites!H$34:H$100,0)) -> 37.145131 | I3: 5 | J3: 5 | K3: 0 | L3: 0 | M3: Y | N3: *aka: SHL2019
B4: Yosemite_National_Park | C4: FVWB | D4: FVWB | E4: 5766 | F4: =INDEX(FieldSites!C$34:C$100, MATCH(FieldSites!C4, FieldSites!H$34:H$100,0)) -> 1757 | G4: =INDEX(FieldSites!A$34:A$100, MATCH(FieldSites!C4, FieldSites!H$34:H$100,0)) -> -119.70272 | H4: =INDEX(FieldSites!B$34:B$100, MATCH(FieldSites!C4, FieldSites!H$34:H$100,0)) -> 37.698587 | I4: 1 | J4: 1 | K4: 0 | L4: 0 | M4: N
A5: Lower Yosemite Falls Trail | B5: Yosemite_National_Park | C5: LYFB | D5: LYFB | E5: 5203 | F5: =INDEX(FieldSites!C$34:C$100, MATCH(FieldSites!C5, FieldSites!H$34:H$100,0)) -> 1565 | G5: =INDEX(FieldSites!A$34:A$100, MATCH(FieldSites!C5, FieldSites!H$34:H$100,0)) -> -119.60139 | H5: =INDEX(FieldSites!B$34:B$100, MATCH(FieldSites!C5, FieldSites!H$34:H$100,0)) -> 37.748823 | I5: 0 | J5: 5 | K5: 0 | L5: 0 | M5: N
A6: Huntington Lake Overview | B6: Sierra_National_Forest | C6: HUOB | D6: HUOB | E6: 6033 | F6: =INDEX(FieldSites!C$34:C$100, MATCH(FieldSites!C6, FieldSites!H$34:H$100,0)) -> 1851 | G6: =INDEX(FieldSites!A$34:A$100, MATCH(FieldSites!C6, FieldSites!H$34:H$100,0)) -> -119.27351 | H6: =INDEX(FieldSites!B$34:B$100, MATCH(FieldSites!C6, FieldSites!H$34:H$100,0)) -> 37.150723 | I6: 0 | J6: 17 | K6: 5 | L6: 0 | M6: Y
A7: Huntington Lake | B7: Sierra_National_Forest | C7: HULB | D7: HULB | E7: 7126 | F7: =INDEX(FieldSites!C$34:C$100, MATCH(FieldSites!C7, FieldSites!H$34:H$100,0)) -> 2178 | G7: =INDEX(FieldSites!A$34:A$100, MATCH(FieldSites!C7, FieldSites!H$34:H$100,0)) -> -119.14962 | H7: =INDEX(FieldSites!B$34:B$100, MATCH(FieldSites!C7, FieldSites!H$34:H$100,0)) -> 37.23553 | I7: 5 | J7: 5 | K7: 0 | L7: 0 | M7: Y
A8: Little Meadow | B8: Yosemite_National_Park | C8: LM | D8: LMZZ | E8: 6250 | F8: =INDEX(FieldSites!C$34:C$100, MATCH(FieldSites!C8, FieldSites!H$34:H$100,0)) -> 2157 | G8: =INDEX(FieldSites!A$34:A$100, MATCH(FieldSites!C8, FieldSites!H$34:H$100,0)) -> -119.77272 | H8: =INDEX(FieldSites!B$34:B$100, MATCH(FieldSites!C8, FieldSites!H$34:H$100,0)) -> 37.767781 | I8: 0 | J8: 10 | K8: 0 | L8: 0 | M8: N
A9: Crane Flat | B9: Yosemite_National_Park | C9: CF | D9: CFZZ | E9: 6237 | F9: =INDEX(FieldSites!C$34:C$100, MATCH(FieldSites!C9, FieldSites!H$34:H$100,0)) -> 1901 | G9: =INDEX(FieldSites!A$34:A$100, MATCH(FieldSites!C9, FieldSites!H$34:H$100,0)) -> -119.80295 | H9: =INDEX(FieldSites!B$34:B$100, MATCH(FieldSites!C9, FieldSites!H$34:H$100,0)) -> 37.755986 | I9: 0 | J9: 10 | K9: 0 | L9: 0 | M9: N
A10: Angel Falls | B10: Sierra_National_Forest | C10: AGFB | D10: AGFB | E10: 3688 | F10: =INDEX(FieldSites!C$34:C$100, MATCH(FieldSites!C10, FieldSites!H$34:H$100,0)) -> 1124 | G10: =INDEX(FieldSites!A$34:A$100, MATCH(FieldSites!C10, FieldSites!H$34:H$100,0)) -> -119.57068 | H10: =INDEX(FieldSites!B$34:B$100, MATCH(FieldSites!C10, FieldSites!H$34:H$100,0)) -> 37.33823 | I10: 10 | J10: 0 | K10: 10 | L10: 0 | M10: Y
C11: BHEB | D11: BHEB | E11: 3967 | F11: =INDEX(FieldSites!C$34:C$100, MATCH(FieldSites!C11, FieldSites!H$34:H$100,0)) -> 1209 | G11: =INDEX(FieldSites!A$34:A$100, MATCH(FieldSites!C11, FieldSites!H$34:H$100,0)) -> -119.39323 | H11: =INDEX(FieldSites!B$34:B$100, MATCH(FieldSites!C11, FieldSites!H$34:H$100,0)) -> 37.053544 | I11: 0 | J11: 10 | K11: 10 | L11: 0 | M11: Y
A12: Hetch Hetchy B | B12: Yosemite_National_Park | C12: HHBB | D12: HHBB | E12: 3934 | F12: =INDEX(FieldSites!C$34:C$100, MATCH(FieldSites!C12, FieldSites!H$34:H$100,0)) -> 1199 | G12: =INDEX(FieldSites!A$34:A$100, MATCH(FieldSites!C12, FieldSites!H$34:H$100,0)) -> -119.77855 | H12: =INDEX(FieldSites!B$34:B$100, MATCH(FieldSites!C12, FieldSites!H$34:H$100,0)) -> 37.959056 | I12: 10 | J12: 10 | K12: 0 | L12: 0 | M12: Y
A13: Turtle Back Dome B | B13: Yosemite_National_Park | C13: TRTB | D13: TRTB | E13: 5158 | F13: =INDEX(FieldSites!C$34:C$100, MATCH(FieldSites!C13, FieldSites!H$34:H$100,0)) -> 1572 | G13: =INDEX(FieldSites!A$34:A$100, MATCH(FieldSites!C13, FieldSites!H$34:H$100,0)) -> -119.71015 | H13: =INDEX(FieldSites!B$34:B$100, MATCH(FieldSites!C13, FieldSites!H$34:H$100,0)) -> 37.700419 | I13: 1 | J13: 0 | L13: 0 | M13: N
A14: Turtle Back Dome | B14: Yosemite_National_Park | C14: TRT | D14: TRTZ | E14: 4875 | F14: =INDEX(FieldSites!C$34:C$100, MATCH(FieldSites!C14, FieldSites!H$34:H$100,0)) -> 1486 | G14: =INDEX(FieldSites!A$34:A$100, MATCH(FieldSites!C14, FieldSites!H$34:H$100,0)) -> -119.70532 | H14: =INDEX(FieldSites!B$34:B$100, MATCH(FieldSites!C14, FieldSites!H$34:H$100,0)) -> 37.716098 | I14: 10 | J14: 0 | K14: 0 | L14: 0 | M14: N | N14: * aka: TRT2019
A15: Tawonga | B15: Stanislaus_National_Forest | C15: TWGB | D15: TWGB | E15: 4793 | F15: =INDEX(FieldSites!C$34:C$100, MATCH(FieldSites!C15, FieldSites!H$34:H$100,0)) -> 1238 | G15: =INDEX(FieldSites!A$34:A$100, MATCH(FieldSites!C15, FieldSites!H$34:H$100,0)) -> -119.95131 | H15: =INDEX(FieldSites!B$34:B$100, MATCH(FieldSites!C15, FieldSites!H$34:H$100,0)) -> 37.85882 | I15: 0 | J15: 10 | K15: 0 | L15: 0 | M15: N
A16: Carson Creek | B16: Mariposa County | C16: CCRB | D16: CCRB | E16: 2081 | F16: =INDEX(FieldSites!C$34:C$100, MATCH(FieldSites!C16, FieldSites!H$34:H$100,0)) -> 666 | G16: =INDEX(FieldSites!A$34:A$100, MATCH(FieldSites!C16, FieldSites!H$34:H$100,0)) -> -119.99792 | H16: =INDEX(FieldSites!B$34:B$100, MATCH(FieldSites!C16, FieldSites!H$34:H$100,0)) -> 37.486337 | I16: 0 | J16: 0 | K16: 10 | L16: 0 | M16: N
A17: North Fork Willow Creek | B17: Sierra_National_Forest | C17: NFWB | D17: NFWB | E17: 2772 | F17: =INDEX(FieldSites!C$34:C$100, MATCH(FieldSites!C17, FieldSites!H$34:H$100,0)) -> 875 | G17: =INDEX(FieldSites!A$34:A$100, MATCH(FieldSites!C17, FieldSites!H$34:H$100,0)) -> -119.52142 | H17: =INDEX(FieldSites!B$34:B$100, MATCH(FieldSites!C17, FieldSites!H$34:H$100,0)) -> 37.257397 | I17: 7 | J17: 0 | K17: 11 | L17: 0 | M17: Y
A18: Wildcat Falls | B18: Yosemite_National_Park | C18: WCFB | D18: WCFB | E18: 4528 | F18: =INDEX(FieldSites!C$34:C$100, MATCH(FieldSites!C18, FieldSites!H$34:H$100,0)) -> 1380 | G18: =INDEX(FieldSites!A$34:A$100, MATCH(FieldSites!C18, FieldSites!H$34:H$100,0)) -> -119.71908 | H18: =INDEX(FieldSites!B$34:B$100, MATCH(FieldSites!C18, FieldSites!H$34:H$100,0)) -> 37.723593 | I18: 11 | J18: 12 | K18: 0 | L18: 0 | M18: Y
A19: Highland Drive Road | B19: Sierra_National_Forest | C19: HDRB | D19: HDRB | E19: 3284 | F19: =INDEX(FieldSites!C$34:C$100, MATCH(FieldSites!C19, FieldSites!H$34:H$100,0)) -> 1037 | G19: =INDEX(FieldSites!A$34:A$100, MATCH(FieldSites!C19, FieldSites!H$34:H$100,0)) -> -119.53471 | H19: =INDEX(FieldSites!B$34:B$100, MATCH(FieldSites!C19, FieldSites!H$34:H$100,0)) -> 37.288671 | I19: 0 | J19: 10 | K19: 0 | L19: 0 | M19: N
A20: Stoddard Spring | B20: Stanislaus_National_Forest | C20: SDSB | D20: SDSB | E20: 5511 | F20: =INDEX(FieldSites!C$34:C$100, MATCH(FieldSites!C20, FieldSites!H$34:H$100,0)) -> 1679 | G20: =INDEX(FieldSites!A$34:A$100, MATCH(FieldSites!C20, FieldSites!H$34:H$100,0)) -> -120.09461 | H20: =INDEX(FieldSites!B$34:B$100, MATCH(FieldSites!C20, FieldSites!H$34:H$100,0)) -> 38.136194 | I20: 0 | J20: 10 | K20: 0 | L20: 10 | M20: Y
A21: Crab Tree Road | B21: Stanislaus_National_Forest | C21: CCNB | D21: CCNB | E21: 6554 | F21: =INDEX(FieldSites!C$34:C$100, MATCH(FieldSites!C21, FieldSites!H$34:H$100,0)) -> 1997 | G21: =INDEX(FieldSites!A$34:A$100, MATCH(FieldSites!C21, FieldSites!H$34:H$100,0)) -> -119.96325 | H21: =INDEX(FieldSites!B$34:B$100, MATCH(FieldSites!C21, FieldSites!H$34:H$100,0)) -> 38.183927 | I21: 0 | J21: 12 | K21: 0 | L21: 4 | M21: Y
A22: Wawona School | B22: Yosemite_National_Park | C22: WSHB | D22: WSHB | E22: 4055 | F22: =INDEX(FieldSites!C$34:C$100, MATCH(FieldSites!C22, FieldSites!H$34:H$100,0)) -> 1235 | G22: =INDEX(FieldSites!A$34:A$100, MATCH(FieldSites!C22, FieldSites!H$34:H$100,0)) -> -119.64788 | H22: =INDEX(FieldSites!B$34:B$100, MATCH(FieldSites!C22, FieldSites!H$34:H$100,0)) -> 37.543343 | I22: 0 | J22: 11 | K22: 0 | L22: 0 | M22: N
A23: Onion Skins | B23: Yosemite_National_Park | C23: OSKB | D23: OSKB | E23: 7808 | F23: =INDEX(FieldSites!C$34:C$100, MATCH(FieldSites!C23, FieldSites!H$34:H$100,0)) -> 2399 | G23: =INDEX(FieldSites!A$34:A$100, MATCH(FieldSites!C23, FieldSites!H$34:H$100,0)) -> -119.59457 | H23: =INDEX(FieldSites!B$34:B$100, MATCH(FieldSites!C23, FieldSites!H$34:H$100,0)) -> 37.842693 | I23: 7 | J23: 0 | K23: 0 | L23: 0 | M23: N
A24: Spotless | B24: Yosemite_National_Park | C24: SPLB | D24: SPLB | E24: 8281 | F24: =INDEX(FieldSites!C$34:C$100, MATCH(FieldSites!C24, FieldSites!H$34:H$100,0)) -> 2348 | G24: =INDEX(FieldSites!A$34:A$100, MATCH(FieldSites!C24, FieldSites!H$34:H$100,0)) -> -119.58613 | H24: =INDEX(FieldSites!B$34:B$100, MATCH(FieldSites!C24, FieldSites!H$34:H$100,0)) -> 37.847194 | I24: 9 | J24: 0 | K24: 0 | L24: 0 | M24: N
A25: Yosemite Creek B | B25: Yosemite_National_Park | C25: YCNB | D25: YCNB | E25: 7736 | F25: =INDEX(FieldSites!C$34:C$100, MATCH(FieldSites!C25, FieldSites!H$34:H$100,0)) -> 2357 | G25: =INDEX(FieldSites!A$34:A$100, MATCH(FieldSites!C25, FieldSites!H$34:H$100,0)) -> -119.57275 | H25: =INDEX(FieldSites!B$34:B$100, MATCH(FieldSites!C25, FieldSites!H$34:H$100,0)) -> 37.843904 | I25: 10 | J25: 0 | K25: 0 | L25: 0 | M25: N
A26: The Knobs | B26: Yosemite_National_Park | C26: KNOB | D26: KNOB | E26: 8442 | F26: =INDEX(FieldSites!C$34:C$100, MATCH(FieldSites!C26, FieldSites!H$34:H$100,0)) -> 2572 | G26: =INDEX(FieldSites!A$34:A$100, MATCH(FieldSites!C26, FieldSites!H$34:H$100,0)) -> -119.44037 | H26: =INDEX(FieldSites!B$34:B$100, MATCH(FieldSites!C26, FieldSites!H$34:H$100,0)) -> 37.853852 | I26: 10 | J26: 0 | K26: 0 | L26: 0 | M26: N
A27: Olmstead Point | B27: Yosemite_National_Park | C27: OPN | D27: OPNZ | E27: 8225 | F27: =INDEX(FieldSites!C$34:C$100, MATCH(FieldSites!C27, FieldSites!H$34:H$100,0)) -> 2506 | G27: =INDEX(FieldSites!A$34:A$100, MATCH(FieldSites!C27, FieldSites!H$34:H$100,0)) -> -119.48631 | H27: =INDEX(FieldSites!B$34:B$100, MATCH(FieldSites!C27, FieldSites!H$34:H$100,0)) -> 37.807232 | I27: 20 | J27: 0 | K27: 0 | L27: 0 | M27: N
B29: *Detailed information on sites can be found in /field_data/gps_points/mim2_lat_long.csv

Sheet Sheet1
A1: AGFB | B1: L | C1: 10 | D1: {=INDEX(FieldSites!E:E, MATCH(Sheet1!A1, FieldSites!C:C,0))} -> 3688
A2: AGFB | B2: L | C2: 5 | D2: {=INDEX(FieldSites!E:E, MATCH(Sheet1!A2, FieldSites!C:C,0))} -> 3688
A3: AGFB | B3: N | C3: 3 | D3: {=INDEX(FieldSites!E:E, MATCH(Sheet1!A3, FieldSites!C:C,0))} -> 3688
A4: BHEB | B4: G | C4: 2 | D4: {=INDEX(FieldSites!E:E, MATCH(Sheet1!A4, FieldSites!C:C,0))} -> 3967
A5: BHEB | B5: G | C5: 3 | D5: {=INDEX(FieldSites!E:E, MATCH(Sheet1!A5, FieldSites!C:C,0))} -> 3967
A6: BHEB | B6: G | C6: 6 | D6: {=INDEX(FieldSites!E:E, MATCH(Sheet1!A6, FieldSites!C:C,0))} -> 3967
A7: BHEB | B7: G | C7: 7 | D7: {=INDEX(FieldSites!E:E, MATCH(Sheet1!A7, FieldSites!C:C,0))} -> 3967
A8: BHEB | B8: G | C8: 8 | D8: {=INDEX(FieldSites!E:E, MATCH(Sheet1!A8, FieldSites!C:C,0))} -> 3967
A9: BHEB | B9: G | C9: 9 | D9: {=INDEX(FieldSites!E:E, MATCH(Sheet1!A9, FieldSites!C:C,0))} -> 3967
A10: BHEB | B10: N | C10: 2 | D10: {=INDEX(FieldSites!E:E, MATCH(Sheet1!A10, FieldSites!C:C,0))} -> 3967
A11: BHEB | B11: N | C11: 4 | D11: {=INDEX(FieldSites!E:E, MATCH(Sheet1!A11, FieldSites!C:C,0))} -> 3967
A12: BHEB | B12: N | C12: 5 | D12: {=INDEX(FieldSites!E:E, MATCH(Sheet1!A12, FieldSites!C:C,0))} -> 3967
... A14: BHEB | B14: N | C14: 8 | D14: {=INDEX(FieldSites!E:E, MATCH(Sheet1!A14, FieldSites!C:C,0))} -> 3967
A15: C-10082022 | D15: {=INDEX(FieldSites!E:E, MATCH(Sheet1!A15, FieldSites!C:C,0))} -> #N/A
A16: C-11052022 | D16: {=INDEX(FieldSites!E:E, MATCH(Sheet1!A16, FieldSites!C:C,0))} -> #N/A
A17: C-8262022 | D17: {=INDEX(FieldSites!E:E, MATCH(Sheet1!A17, FieldSites!C:C,0))} -> #N/A
A18: C-9302022 | D18: {=INDEX(FieldSites!E:E, MATCH(Sheet1!A18, FieldSites!C:C,0))} -> #N/A
A19: C-A12192022 | D19: {=INDEX(FieldSites!E:E, MATCH(Sheet1!A19, FieldSites!C:C,0))} -> #N/A
A20: CCNB | B20: G | C20: 4 | D20: {=INDEX(FieldSites!E:E, MATCH(Sheet1!A20, FieldSites!C:C,0))} -> 6554
A21: CCRB | B21: N | C21: 1 | D21: {=INDEX(FieldSites!E:E, MATCH(Sheet1!A21, FieldSites!C:C,0))} -> 2081
A22: CCRB | B22: N | C22: 1 | D22: {=INDEX(FieldSites!E:E, MATCH(Sheet1!A22, FieldSites!C:C,0))} -> 2081
A23: CCRB | B23: N | C23: 2 | D23: {=INDEX(FieldSites!E:E, MATCH(Sheet1!A23, FieldSites!C:C,0))} -> 2081
A24: CCRB | B24: N | C24: 3 | D24: {=INDEX(FieldSites!E:E, MATCH(Sheet1!A24, FieldSites!C:C,0))} -> 2081
A25: CCRB | B25: N | C25: 6 | D25: {=INDEX(FieldSites!E:E, MATCH(Sheet1!A25, FieldSites!C:C,0))} -> 2081
A26: CCRB | B26: N | C26: 7 | D26: {=INDEX(FieldSites!E:E, MATCH(Sheet1!A26, FieldSites!C:C,0))} -> 2081
A27: HDRB | B27: G | C27: 1 | D27: {=INDEX(FieldSites!E:E, MATCH(Sheet1!A27, FieldSites!C:C,0))} -> 3284
A28: HDRB | B28: G | C28: 10 | D28: {=INDEX(FieldSites!E:E, MATCH(Sheet1!A28, FieldSites!C:C,0))} -> 3284
A29: HDRB | B29: G | C29: 2 | D29: {=INDEX(FieldSites!E:E, MATCH(Sheet1!A29, FieldSites!C:C,0))} -> 3284
A30: HDRB | B30: G | C30: 2 | D30: {=INDEX(FieldSites!E:E, MATCH(Sheet1!A30, FieldSites!C:C,0))} -> 3284
A31: HDRB | B31: G | C31: 5 | D31: {=INDEX(FieldSites!E:E, MATCH(Sheet1!A31, FieldSites!C:C,0))} -> 3284
... A56: OSKB | B56: L | C56: 1 | D56: {=INDEX(FieldSites!E:E, MATCH(Sheet1!A56, FieldSites!C:C,0))} -> 7808
A57: PCR- | D57: {=INDEX(FieldSites!E:E, MATCH(Sheet1!A57, FieldSites!C:C,0))} -> #N/A
A58: PCR+* | D58: {=INDEX(FieldSites!E:E, MATCH(Sheet1!A58, FieldSites!C:C,0))} -> #N/A
A59: SDSB | B59: G | C59: 10 | D59: {=INDEX(FieldSites!E:E, MATCH(Sheet1!A59, FieldSites!C:C,0))} -> 5511
A60: SDSB | B60: G | C60: 2 | D60: {=INDEX(FieldSites!E:E, MATCH(Sheet1!A60, FieldSites!C:C,0))} -> 5511
A61: SDSB | B61: G | C61: 3 | D61: {=INDEX(FieldSites!E:E, MATCH(Sheet1!A61, FieldSites!C:C,0))} -> 5511
A62: SDSB | B62: G | C62: 5 | D62: {=INDEX(FieldSites!E:E, MATCH(Sheet1!A62, FieldSites!C:C,0))} -> 5511
A63: SDSB | B63: G | C63: 8 | D63: {=INDEX(FieldSites!E:E, MATCH(Sheet1!A63, FieldSites!C:C,0))} -> 5511
A64: SDSB | B64: G | C64: 9 | D64: {=INDEX(FieldSites!E:E, MATCH(Sheet1!A64, FieldSites!C:C,0))} -> 5511
A65: SPLB | B65: L | C65: 1 | D65: {=INDEX(FieldSites!E:E, MATCH(Sheet1!A65, FieldSites!C:C,0))} -> 8281
...

Sheet DNA_PCR_progress
A1: Site | B1: Population | C1: Species | D1: Hybrid | E1: Sample | F1: Sequen_ID | G1: Unique_ID | H1: Extrac_event | I1: Sample_Date | J1: Subsampled | K1: Subsampling_Qotes | L1: Lyophilized | M1: DNA_extr | N1: Extr_date | O1: DNA_conc._ng/µl | P1: Extr_Box | Q1: Extraction_Method | R1: Extr_notes | S1: PCR1 | T1: PCR2 | V1: sample_control
B2: C- | E2: 9302022 | F2: =CONCATENATE(B2,"",C2,E2) -> C-9302022 | G2: C-9302022 | H2: 1 | I2: 44834 | J2: QA | L2: 0 | M2: 1 | N2: 44834 | O2: too low | P2: 1 | Q2: =IF(ISBLANK(N5),"",IF(N5<DATE(2023,5,1),"OLD","NEW")) -> OLD | S2: =IF(COUNTIF('[1]Plate_1-2_LongFormat'!$A$2:$A$193,G2)>0,1,0) -> 1 | T2: =IF(COUNTIF([2]Attached_indexes!$C$2:$C$193,G2)>0,1,0) -> 1 | U2: =_xlfn.T.TEST(O68:O79, O89:O91,2,2) -> 5.832148e-07 | V2: control
B3: C- | E3: 8262022 | F3: =CONCATENATE(B3,"",C3,E3) -> C-8262022 | G3: C8262022 | H3: 1 | I3: 44799 | J3: NA | L3: 0 | M3: 1 | N3: 44799 | O3: too low | P3: 1 | Q3: =IF(ISBLANK(N6),"",IF(N6<DATE(2023,5,1),"OLD","NEW")) -> OLD | S3: =IF(COUNTIF('[1]Plate_1-2_LongFormat'!$A$2:$A$193,G3)>0,1,0) -> 0 | T3: =IF(COUNTIF([2]Attached_indexes!$C$2:$C$193,G3)>0,1,0) -> 0 | U3: {=_xlfn.T.TEST(INDEX($O$37:$O$1144,MATCH("OLD",$Q$37:$Q$1144,0)):INDEX($O$37:$O$1144,MATCH("OLD",$Q$37:$Q$1144,0)+COUNTIF($Q$37:$Q$1144,"OLD")-1),INDEX($O$37:$O$1144,MATCH("NEW",$Q$37:$Q$1144,0)):INDEX($O$37:$O$1144,MATCH("NEW",$Q$37:$Q$1144,0)+COUNTIF($Q$37:$Q$1144,"NEW")-1),2,2)} -> 0.3614 | V3: control
G4: S1 | H4: 1 | I4: 44834 | J4: NA | L4: 0 | M4: 1 | N4: 44834 | O4: 30.05 | P4: 1 | Q4: =IF(ISBLANK(N7),"",IF(N7<DATE(2023,5,1),"OLD","NEW")) -> OLD | S4: =IF(COUNTIF('[1]Plate_1-2_LongFormat'!$A$2:$A$193,G4)>0,1,0) -> 0 | T4: =IF(COUNTIF([2]Attached_indexes!$C$2:$C$193,G4)>0,1,0) -> 0 | V4: control
G5: S1 | H5: 1 | I5: 44799 | J5: NA | L5: 0 | M5: 1 | N5: 44799 | O5: 27.41 | P5: 1 | Q5: =IF(ISBLANK(N5),"",IF(N5<DATE(2023,5,1),"OLD","NEW")) -> OLD | S5: =IF(COUNTIF('[1]Plate_1-2_LongFormat'!$A$2:$A$193,G5)>0,1,0) -> 0 | T5: =IF(COUNTIF([2]Attached_indexes!$C$2:$C$193,G5)>0,1,0) -> 0 | V5: control
G6: S2 | H6: 1 | I6: 44834 | J6: NA | L6: 0 | M6: 1 | N6: 44834 | O6: 13728.67 ng/mL | P6: 1 | Q6: =IF(ISBLANK(N6),"",IF(N6<DATE(2023,5,1),"OLD","NEW")) -> OLD | S6: =IF(COUNTIF('[1]Plate_1-2_LongFormat'!$A$2:$A$193,G6)>0,1,0) -> 0 | T6: =IF(COUNTIF([2]Attached_indexes!$C$2:$C$193,G6)>0,1,0) -> 0 | V6: control
G7: S2 | H7: 1 | I7: 44799 | J7: NA | L7: 0 | M7: 1 | N7: 44799 | O7: 11735.15 | P7: 1 | Q7: =IF(ISBLANK(N7),"",IF(N7<DATE(2023,5,1),"OLD","NEW")) -> OLD | S7: =IF(COUNTIF('[1]Plate_1-2_LongFormat'!$A$2:$A$193,G7)>0,1,0) -> 0 | T7: =IF(COUNTIF([2]Attached_indexes!$C$2:$C$193,G7)>0,1,0) -> 0 | V7: control
B8: C- | E8: 10082022 | F8: =CONCATENATE(B8,"",C8,E8) -> C-10082022 | G8: C10082022 | H8: 1 | I8: 44842 | J8: NA | L8: 0 | M8: 1 | N8: 44842 | O8: too low | Q8: =IF(ISBLANK(N8),"",IF(N8<DATE(2023,5,1),"OLD","NEW")) -> OLD | S8: =IF(COUNTIF('[1]Plate_1-2_LongFormat'!$A$2:$A$193,G8)>0,1,0) -> 0 | T8: =IF(COUNTIF([2]Attached_indexes!$C$2:$C$193,G8)>0,1,0) -> 0 | V8: control
F9: =CONCATENATE(B9,"",C9,E9) | G9: S1 | H9: 1 | I9: 44842 | J9: NA | L9: 0 | M9: 1 | N9: 44842 | O9: 32.62 | Q9: =IF(ISBLANK(N9),"",IF(N9<DATE(2023,5,1),"OLD","NEW")) -> OLD | S9: =IF(COUNTIF('[1]Plate_1-2_LongFormat'!$A$2:$A$193,G9)>0,1,0) -> 0 | T9: =IF(COUNTIF([2]Attached_indexes!$C$2:$C$193,G9)>0,1,0) -> 0 | V9: control
F10: =CONCATENATE(B10,"",C10,E10) | G10: S2 | H10: 1 | I10: 44842 | J10: NA | L10: 0 | M10: 1 | N10: 44842 | O10: 14010.53 | Q10: =IF(ISBLANK(N10),"",IF(N10<DATE(2023,5,1),"OLD","NEW")) -> OLD | S10: =IF(COUNTIF('[1]Plate_1-2_LongFormat'!$A$2:$A$193,G10)>0,1,0) -> 0 | T10: =IF(COUNTIF([2]Attached_indexes!$C$2:$C$193,G10)>0,1,0) -> 0 | V10: control
B11: C- | E11: 11052022 | F11: =CONCATENATE(B11,"",C11,E11) -> C-11052022 | G11: C11052022 | H11: 1 | L11: 0 | M11: 1 | N11: 44870 | O11: too low | P11: 2 | Q11: =IF(ISBLANK(N11),"",IF(N11<DATE(2023,5,1),"OLD","NEW")) -> OLD | S11: =IF(COUNTIF('[1]Plate_1-2_LongFormat'!$A$2:$A$193,G11)>0,1,0) -> 0 | T11: =IF(COUNTIF([2]Attached_indexes!$C$2:$C$193,G11)>0,1,0) -> 0 | V11: control
F12: =CONCATENATE(B12,"",C12,E12) | G12: S1 | H12: 1 | L12: 0 | M12: 1 | N12: 44870 | O12: 31.35 | Q12: =IF(ISBLANK(N12),"",IF(N12<DATE(2023,5,1),"OLD","NEW")) -> OLD | S12: =IF(COUNTIF('[1]Plate_1-2_LongFormat'!$A$2:$A$193,G12)>0,1,0) -> 0 | T12: =IF(COUNTIF([2]Attached_indexes!$C$2:$C$193,G12)>0,1,0) -> 0 | V12: control
F13: =CONCATENATE(B13,"",C13,E13) | G13: S2 | H13: 1 | L13: 0 | M13: 1 | N13: 44870 | O13: 14004.19 | Q13: =IF(ISBLANK(N13),"",IF(N13<DATE(2023,5,1),"OLD","NEW")) -> OLD | S13: =IF(COUNTIF('[1]Plate_1-2_LongFormat'!$A$2:$A$193,G13)>0,1,0) -> 0 | T13: =IF(COUNTIF([2]Attached_indexes!$C$2:$C$193,G13)>0,1,0) -> 0 | V13: control
B14: C- | E14: 12192022 | F14: =CONCATENATE(B14,"",C14,E14) -> C-12192022 | G14: C12192022 | H14: 1 | L14: 0 | M14: 1 | N14: 44914 | O14: too low | P14: 2 | Q14: =IF(ISBLANK(N14),"",IF(N14<DATE(2023,5,1),"OLD","NEW")) -> OLD | S14: =IF(COUNTIF('[1]Plate_1-2_LongFormat'!$A$2:$A$193,G14)>0,1,0) -> 0 | T14: =IF(COUNTIF([2]Attached_indexes!$C$2:$C$193,G14)>0,1,0) -> 0 | V14: control
F15: =CONCATENATE(B15,"",C15,E15) | G15: S1 | H15: 1 | L15: 0 | M15: 1 | N15: 44914 | O15: 44.61 | Q15: =IF(ISBLANK(N15),"",IF(N15<DATE(2023,5,1),"OLD","NEW")) -> OLD | S15: =IF(COUNTIF('[1]Plate_1-2_LongFormat'!$A$2:$A$193,G15)>0,1,0) -> 0 | T15: =IF(COUNTIF([2]Attached_indexes!$C$2:$C$193,G15)>0,1,0) -> 0 | V15: control
F16: =CONCATENATE(B16,"",C16,E16) | G16: S2 | H16: 1 | L16: 0 | M16: 1 | N16: 44914 | O16: 8237.26 | Q16: =IF(ISBLANK(N16),"",IF(N16<DATE(2023,5,1),"OLD","NEW")) -> OLD | S16: =IF(COUNTIF('[1]Plate_1-2_LongFormat'!$A$2:$A$193,G16)>0,1,0) -> 0 | T16: =IF(COUNTIF([2]Attached_indexes!$C$2:$C$193,G16)>0,1,0) -> 0 | V16: control
B17: C- | C17: B | E17: 12192022 | F17: =CONCATENATE(B17,"",C17,E17) -> C-B12192022 | G17: CB12192022 | H17: 1 | L17: 0 | M17: 1 | N17: 44914 | O17: too low | P17: 2 | Q17: =IF(ISBLANK(N17),"",IF(N17<DATE(2023,5,1),"OLD","NEW")) -> OLD | S17: =IF(COUNTIF('[1]Plate_1-2_LongFormat'!$A$2:$A$193,G17)>0,1,0) -> 0 | T17: =IF(COUNTIF([2]Attached_indexes!$C$2:$C$193,G17)>0,1,0) -> 0 | V17: control
B18: C- | C18: A | E18: 12192022 | F18: =CONCATENATE(B18,"",C18,E18) -> C-A12192022 | G18: CA12192022 | H18: 1 | L18: 0 | M18: 1 | N18: 44914 | O18: too low | P18: 2 | Q18: =IF(ISBLANK(N18),"",IF(N18<DATE(2023,5,1),"OLD","NEW")) -> OLD | S18: =IF(COUNTIF('[1]Plate_1-2_LongFormat'!$A$2:$A$193,G18)>0,1,0) -> 0 | T18: =IF(COUNTIF([2]Attached_indexes!$C$2:$C$193,G18)>0,1,0) -> 0 | V18: control
B19: C- | C19: A | E19: 1122023 | F19: =CONCATENATE(B19,"",C19,E19) -> C-A1122023 | G19: CA1122023 | H19: 1 | L19: 0 | M19: 1 | N19: 44938 | O19: too low | P19: 2 | Q19: =IF(ISBLANK(N19),"",IF(N19<DATE(2023,5,1),"OLD","NEW")) -> OLD | S19: =IF(COUNTIF('[1]Plate_1-2_LongFormat'!$A$2:$A$193,G19)>0,1,0) -> 0 | T19: =IF(COUNTIF([2]Attached_indexes!$C$2:$C$193,G19)>0,1,0) -> 0 | V19: control
B20: C- | C20: B | E20: 1122023 | F20: =CONCATENATE(B20,"",C20,E20) -> C-B1122023 | G20: CB1122023 | H20: 1 | L20: 0 | M20: 1 | N20: 44938 | O20: too low | Q20: =IF(ISBLANK(N20),"",IF(N20<DATE(2023,5,1),"OLD","NEW")) -> OLD | S20: =IF(COUNTIF('[1]Plate_1-2_LongFormat'!$A$2:$A$193,G20)>0,1,0) -> 0 | T20: =IF(COUNTIF([2]Attached_indexes!$C$2:$C$193,G20)>0,1,0) -> 0 | V20: control
B21: S1 | E21: 1162023 | F21: =CONCATENATE(B21,"",C21,E21) -> S11162023 | G21: =_xludf.concat(C21,D21,F21) -> #NAME? | H21: 1 | L21: 0 | M21: 0 | Q21: =IF(ISBLANK(N21),"",IF(N21<DATE(2023,5,1),"OLD","NEW")) | S21: =IF(COUNTIF('[1]Plate_1-2_LongFormat'!$A$2:$A$193,G21)>0,1,0) -> #NAME? | T21: =IF(COUNTIF([2]Attached_indexes!$C$2:$C$193,G21)>0,1,0) -> #NAME? | V21: control
